Workbook
Name Q_53: 'Work 3'!$C$9
Name Q_08: 'Part A'!$C$12
Name SYN_1: Synthesis!$C$5
Name SYN_3: Synthesis!$C$7
Name Q_04: 'Part A'!$C$8
Name Q_16: 'Part A'!$C$20
Name EXP_5: 'Work 2'!$E$10
Name Q_88: 'Work 7'!$D$44
Name Q_05: 'Part A'!$C$9
Name Q_64: 'Work 3'!$C$20
Name Q_23: 'Part B'!$C$7
Name Q_86: 'Work 6'!$C$9
Name Q_55: 'Work 3'!$C$11
Name Q_95: 'Work 7'!$D$51
Name Q_07: 'Part A'!$C$11
Name Q_49: 'Work 3'!$C$5
Name Q_79: 'Work 5'!$C$6
Name Q_34: 'Work 1'!$C$14
Name Q_02: 'Part A'!$C$6
Name SYN_2: Synthesis!$C$6
Name Q_72: 'Work 4'!$C$12
Name Q_61: 'Work 3'!$C$17
Name Q_35: 'Work 1'!$C$15
Name Q_18: 'Part A'!$C$22
Name Q_89: 'Work 7'!$D$45
Name Q_80: 'Work 5'!$C$7
Name Q_99: 'Work 7'!$D$55
Name Q_92: 'Work 7'!$D$48
Name EXP_2: 'Work 2'!$E$7
Name Q_42: 'Work 2'!$C$7
Name Q_30: 'Part B'!$C$14
Name FIX_L1: 'Work 7'!$E$44
Name Q_58: 'Work 3'!$C$14
Name Q_15: 'Part A'!$C$19
Name Q_60: 'Work 3'!$C$16
Name Q_43: 'Work 2'!$C$8
Name FIX_L11: 'Work 7'!$E$54
Name Q_62: 'Work 3'!$C$18
Name Q_31: 'Work 1'!$C$11
Name Q_12: 'Part A'!$C$16
Name Q_85: 'Work 6'!$C$8
Name Q_13: 'Part A'!$C$17
Name Q_45: 'Work 2'!$C$10
Name FIX_L4: 'Work 7'!$E$47
Name Q_29: 'Part B'!$C$13
Name Q_91: 'Work 7'!$D$47
Name FIX_L8: 'Work 7'!$E$51
Name FIX_L3: 'Work 7'!$E$46
Name Q_56: 'Work 3'!$C$12
Name Q_75: 'Work 4'!$C$15
Name FIX_L5: 'Work 7'!$E$48
Name Q_25: 'Part B'!$C$9
Name Q_76: 'Work 4'!$C$16
Name Q_97: 'Work 7'!$D$53
Name Q_71: 'Work 4'!$C$11
Name Q_68: 'Work 4'!$C$8
Name Q_81: 'Work 5'!$C$8
Name Q_93: 'Work 7'!$D$49
Name Q_36: 'Work 1'!$C$16
Name Q_06: 'Part A'!$C$10

Sheet Read Me
A1: Intermediate Checkpoint Assessment, Form 1 | Z1: 1
A4: Your name (Last, First) | B4: Student, Sample
A5: Cohort and school | B5: Intermediate Cohort, Sample School
A7: Steps
A8: Step 1 | B8: Type your name and cohort in the yellow cells above.
A9: Step 2
A10: Step 3 | B10: Answer every yellow cell on Part A and Part B.
A11: Step 4 | B11: Read Case Exhibits. Do not change Case Exhibits or columns A to J of the Data Pack. Add helper columns to the right of the Data Pack if you need them.
A12: Step 5 | B12: On Work 1 to Work 6, fill every yellow cell with a formula, except drop-down cells (pick from the list) and the Work 2 reason cells (write text). Reference the Data Pack, Case Exhibits, the blue inputs on that tab, or your own earlier Work tabs. A scored answer typed in as a number scores zero.
A13: Step 6 | B13: On Work 2, write a one-line reason for every treatment. Cite the fact in the diligence note or exhibit that decides it.
A14: Step 7 | B14: On Work 3, build the Data Table with Data > What-If Analysis > Data Table.
A15: Step 8 | B15: On Work 7, choose a finding for every line. Write a one-line fix for every line you do not mark OK.
A16: Step 9 | B16: On Synthesis, answer every prompt in full sentences. Cite figures from your Work tabs.
A17: Step 10 | B17: Open Self-Check. Fix every line that reads CHECK.
A18: Step 11 | B18: Save the file as LASTNAME_Firstname_INT_Form1.xlsx. Upload it at the link you were sent, before the deadline.
A20: How to enter answers
A21: Dollars | B21: $ in millions on every tab except the Data Pack (dollars) and the property on Work 6 (whole dollars).
A22: Percentages | B22: Return a decimal: a formula that gives 0.234 displays as 23.4%.
A23: Multiples | B23: Return the number: 2.4 displays as 2.40x.
A24: Choices | B24: Pick from the drop-down list in the cell.
A25: Precision | B25: Round only at the end. Carry full precision through your work.
A26: Colors | B26: Blue = input. Black = formula. Green = link to another tab. Scored cells have an orange border.
A27: Circularity | B27: Work 3 uses average-balance interest. Iterative calculation is on in this file.
A29: Scoring
A30: Part A | B30: Items 1-20. Multiple choice, 1 point each. 20 points.
A31: Part B | B31: Items 21-30. True or false, 0.5 point each. 5 points.
A32: Work 1 | B32: Items 31-40. Data Pack analysis. 10 points.
A33: Work 2 | B33: Items 41-48. Underwriting EBITDA: each treatment 0.5, each written reason 0.5, the underwriting EBITDA 1 point. 8 points.
A34: Work 3 | B34: Items 49-64. Sources and uses, debt schedule and returns. 16 points.
A35: Work 4 | B35: Items 65-77. Credit solvency. 13 points.
A36: Work 5 | B36: Items 78-81. Recovery waterfall. 4 points.
A37: Work 6 | B37: Items 82-87. Real estate and cross-asset comparison. 6 points.
A38: Work 7 | B38: Items 88-99. Self-audit findings, 0.5 point each, plus 2 points for the fixes. 8 points.
A39: Synthesis | B39: Five written answers, 2 points each. 10 points.
A40: Total | B40: 100 points.
A42: Bramble Hill Foods, Kestrel Bakeries, Alder Court Apartments and every other company in this workbook are illustrative. The Data Pack is constructed for this assessment.

Sheet Part A
A1: Part A. Multiple choice: items 1-20, 1 point each
A2: Choose A, B, C or D in the yellow cell. Items 1-20 are about other companies, not Project Bramble.
A4: Item | B4: Question | C4: Answer
A5: 1 | B5: A fellow's forecast balance sheet balances in Year 1. In Year 2, total assets exceed liabilities plus equity by exactly the Year 2 increase in accounts receivable. What is the most likely cause? A. Interest expense was left out of both the income statement and the cash flow statement B. Depreciation was added back twice in cash flow from operations, overstating the cash balance C. The receivables increase was never deducted in cash flow from operations D. The dividend was deducted from retained earnings but never deducted from the cash balance | C5: C
A6: 2 | B6: A debt schedule uses average-balance interest, a cash sweep and iterative calculation. A fellow typed text into the Year 1 EBITDA cell by mistake, then restored the formula. Every year still shows #VALUE!. What clears it? A. Move the debt schedule above the working capital schedule so it calculates first B. Hardcode Year 1 interest at last year's figure so the loop has a fixed starting point C. Switch interest to the opening balance, let it recalculate, then switch back D. Delete the minimum cash balance so the sweep can never produce a negative figure | C6: B
A7: 3 | B7: A sponsor offers $32.00 per share for a company with 60.0m basic shares and 4.0m in-the-money options at a $24.00 average exercise price. Using the treasury stock method, what is the equity purchase price? A. $1,920.0m B. $2,048.0m C. $2,016.0m D. $1,952.0m | C7: D
A8: 4 | B8: Two base cases for the same buyout, bought at 8.0x, reach the same IRR. Case X exits at 9.5x with 4% annual EBITDA growth. Case Y exits at 8.0x with 7% growth, backed by signed price increases and a new contract. Which base case should the memo lead with? A. Case X, because growth assumptions are harder to defend than an exit multiple B. Either one, because the two cases produce the same IRR and the same MOIC C. Case X, because a higher exit multiple is the market's own view of business quality D. Case Y, because its return rests on operating results the team can diligence | C8: B
A9: 5 | B9: A CIM shows Adjusted EBITDA up 18%. The invoice data shows the largest customer's share of revenue rose from 20% to 29%, and its gross margin fell 4 points. What does this mean for a lender? A. Earnings lean more on one customer already pushing price down; stress that customer B. The margin decline matters to the equity investor, but not to the lender's repayment C. Nothing, because more revenue from the top customer shows a strong relationship D. Debt capacity rises, because 18% EBITDA growth supports more debt at the same multiple | C9: A
A10: 6 | B10: A fund's hurdle is a 20% IRR. Deal A: base case 25% IRR, downside 0.6x MOIC. Deal B: base case 21% IRR, downside 1.2x MOIC. Both fit the mandate. Which recommendation is best supported? A. Deal A, because it has the highest base-case return and also clears the hurdle B. Neither, because Deal B's base-case return is lower than Deal A's base-case return C. Deal B, because it clears the hurdle and keeps the equity whole in the downside D. Deal A, because a 0.6x downside is within the normal range for a leveraged buyout | C10: C
A11: 7 | B11: A snack maker needs up to $6.0m of extra working capital each autumn and repays it by spring. Which facility fits that need? A. A larger term loan B drawn at close and repaid over seven years B. A five-year bond issued now and held in cash until needed C. A seller note that accrues interest and is repaid at exit D. A revolving credit facility sized to the seasonal peak | C11: D
A12: 8 | B12: A company has an undrawn $15m revolver. Its leverage covenant, tested each quarter, is a 5.0x maximum; leverage today is 4.8x. EBITDA is forecast to fall 10% next quarter with debt unchanged. The sponsor says liquidity is covered. What is the strongest objection? A. The commitment fee on the undrawn amount makes the revolver too costly to keep B. Leverage would rise to about 5.3x, a breach that can block the draw when the cash is needed C. Revolvers are priced above term loans, so drawing on one is uneconomic for the sponsor D. Revolver borrowings cannot be redrawn once they have been repaid from cash flow | C12: B
A13: 9 | B13: Two companies each earn $20m of EBITDA. One sells software on multi-year subscriptions. The other distributes building products and saw EBITDA fall 35% in the last downturn. Lenders offer both 5.0x. What is the best assessment? A. The software company can carry less, because it owns far fewer hard assets B. Both can carry 5.0x, because the EBITDA multiple is what sets debt capacity C. The distributor can carry more, because its inventory and receivables are collateral D. The distributor can safely carry less: its EBITDA falls hardest when debt is due | C13: D
A14: 10 | B14: LTM EBITDA is 12.0. Cash interest is 4.0, cash taxes 1.0, capex 3.0, the increase in net working capital 2.0, and mandatory amortization 1.5 ($ millions). How much cash is available for optional debt repayment? A. 0.5 B. 2.5 C. 2.0 D. 4.5 | C14: A
A15: 11 | B15: A credit agreement requires leverage at or below 5.0x at every quarter-end. It allows a dividend only if leverage after the dividend is at or below 4.0x. Leverage is 4.6x. Which is true? A. It is in default under the quarterly test and cannot pay a dividend B. It complies with the quarterly test and can also pay a dividend now C. It must repay debt down to 4.0x before the next quarter-end test D. It complies with the quarterly test but cannot pay a dividend now | C15: D
A16: 12 | B16: A restricted-payments basket equals $5m, plus 50% of cumulative net income, plus 100% of equity raised, less dividends already paid. Since closing, the borrower has earned $30m, raised $4m of equity and paid $12m of dividends. How much more can it pay? A. $22m B. $24m C. $12m D. $7m | C16: C
... A24: 20 | B24: Two days before the investment committee, you find a model error that cuts the base-case IRR from 22% to 19%, below the 20% hurdle. What do you do? A. Fix it and send the corrected figures and impact to the committee before it meets B. Postpone the committee without explaining why, and fix the model in the meantime C. Present as planned and raise the error only if a committee member asks about it D. Raise the exit multiple by 0.5x so the IRR is back at the 20% hurdle before the meeting | C24: A

Sheet Part B
A1: Part B. True or false: items 21-30, 0.5 point each
A2: Choose True or False in the yellow cell. Items 21-30 are about other companies, not Project Bramble.
A4: Item | B4: Statement | C4: Answer
A5: 21 | B5: A cash sweep repays 3.0 of a term loan during Year 1. Year 1 interest calculated on the average balance is lower than interest calculated on the opening balance. | C5: True
A6: 22 | B6: Collateral worth 40 secures a first lien claim of 50. Unsecured claims are 30. After the collateral is paid out, 16 of value remains and is shared pro rata among all unsecured claims, including the first lien's shortfall. The first lien recovers more than 40 in total. | C6: True
A7: 23 | B7: A building has NOI of $500,000 and annual debt service of $400,000, and the owner invested $3.0m of equity. Its cash-on-cash return is 16.7%. | C7: False
A8: 24 | B8: A borrower at 4.4x leverage faces a 4.5x maximum for taking on new debt. It can borrow another 1.0x of EBITDA and still meet that test. | C8: False
A9: 25 | B9: A base case returns 2.2x MOIC. The downside cuts revenue growth by 1 point, changes nothing else, and returns 2.1x. This shows the deal holds up in a downturn. | C9: False
A10: 26 | B10: EBITDA is 10.0, capex 4.0, cash taxes 1.0, cash interest 3.0 and mandatory amortization 1.0. Fixed-charge coverage, (EBITDA - capex - cash taxes) / (interest + mandatory amortization), is 1.25x, leaving 1.0 of cash after contractual payments. | C10: True
A11: 27 | B11: A company's unhedged term loan B pays SOFR plus a fixed spread. If SOFR rises 2 points, its interest coverage falls even though nothing in the business has changed. | C11: True
A12: 28 | B12: A customer that is 30% of revenue signs a five-year contract with minimum volumes covering 80% of its current purchases. The lender can now model no loss from that customer in the downside. | C12: False
A13: 29 | B13: A CIM adds back run-rate savings from a plant closure that has not started. A lender sizing debt should include the full add-back, because management has committed to the closure. | C13: False
A14: 30 | B14: Two sponsors buy the same company for $100m, one with 25% equity and one with 45%, the rest in senior debt. If the company is later sold for $60m, the lender to the 25%-equity deal loses more. | C14: True

Sheet Case Exhibits
A1: Project Bramble: Bramble Hill Foods ($ in millions unless stated)
A2: Read-only. Reference these cells from your Work tabs.
A4: Exhibit 1. Company and CIM summary
A5: Bramble Hill Foods makes granola, nut butters and snack bars sold to grocers, club stores and online.
A6: LTM = Jul-25 to Jun-26. Prior LTM = Jul-24 to Jun-25. The sponsor would close at the end of the LTM period.
A7: The Data Pack tab holds every invoice line for Jul-24 to Jun-26, exported from the company's system (dollars).
A8: The Data Pack contains five records to exclude: a repeated invoice number (keep the first), a record with negative units, a record with no customer, a record dated outside Jul-24 to Jun-26, and a record whose unit price is more than 5x the product's average price.
A9: Crestline Grocers gave written notice after the LTM period closed that it will not renew its supply agreement. Its last order ships in the quarter after closing.
A11: CIM: FY2025 revenue (Jan-Dec 2025) | B11: 59.9
A12: CIM: FY2025 gross margin | B12: 0.323
A13: CIM: FY2025 reported EBITDA | B13: 7.2
A15: Exhibit 2. Management EBITDA bridge, LTM | B15: $M | D15: Diligence note
A16: Reported EBITDA | B16: 7.6
A17: Add-back: Founder compensation above market | B17: 0.65 | D17: The founder is paid 1.10 a year and retires at close. A search firm quotes 0.45 all-in for a replacement CEO. The 0.65 is already net of the replacement's cost.
A18: Add-back: Co-packer litigation settlement | B18: 0.4 | D18: One dispute with a former co-packer, settled in the LTM period. Counsel confirms no other open claims.
A19: Add-back: Second-line start-up costs | B19: 0.6 | D19: The second production line started in the LTM period. Scrap and overtime ran 0.60 above normal. The line is at 70% utilization; the plant manager expects scrap to settle over the next two quarters.
A20: Add-back: Pro forma list-price increase | B20: 0.85 | D20: An 8% list-price increase was announced after the LTM period. No customer has accepted it. Management applied it to LTM volume.
A21: Add-back: New-product slotting fees | B21: 0.35 | D21: Management calls slotting fees and launch promotions for new items one-time. The company has launched new items in each of the last four years.
A22: Add-back: Freight contract savings | B22: 0.4 | D22: A signed freight contract lowers rates from the last month of the LTM period. One month of savings is in reported EBITDA; management adds back the other eleven.
A23: Management Adjusted EBITDA | B23: =SUM(B16:B22)
A24: Haircut inclusion % | B24: 0.5
A26: Exhibit 3. Working capital and LTM cash items | B26: Jun-25 | C26: Jun-26
A27: Accounts receivable | B27: 6.1 | C27: 6.7
A28: Inventory | B28: 8.4 | C28: 8.85
A29: Prepaid expenses | B29: 0.55 | C29: 0.6
A30: Accounts payable | B30: 4.9 | C30: 5.3
A31: Accrued liabilities | B31: 1.6 | C31: 1.75
A32: LTM capital expenditures (total; use on Work 4) | B32: 2.4
A33: LTM depreciation and amortization | B33: 1.8
A34: Cash tax rate | B34: 0.25
A36: Exhibit 4. Transaction terms and term sheet | D36: Terms
A37: Bid multiple of Management Adjusted EBITDA | B37: 6.75 | D37: Cash-free, debt-free: enterprise value is the price paid for the equity.
A38: Advisory and other fees, % of enterprise value | B38: 0.02
A39: Financing fees, % of term loan B | B39: 0.025
A40: Minimum cash funded at close | B40: 2 | D40: A use of funds. Cash stays at this level; cash above it sweeps to the term loan B.
A41: Fair value of net identifiable assets acquired | B41: 24 | D41: Goodwill = enterprise value less this figure.
A42: Term loan B size, multiple of Management Adjusted EBITDA | B42: 3.5 | D42: Senior secured. Seven-year term.
A43: SOFR | B43: 0.0425
A44: Term loan B spread | B44: 0.0475
A45: Term loan B all-in rate | B45: =B43+B44 | D45: Interest on the average of opening and closing balance.
...

Sheet Data Pack
A1: Data Pack: invoice lines, Jul-24 to Jun-26 (dollars)
A2: Do not change columns A to J. Add helper columns from column K.
A4: Invoice | B4: Month | C4: Customer ID | D4: Customer | E4: Channel | F4: Product | G4: Units (cases) | H4: Net price per case | I4: Revenue | J4: COGS | K4: Period (Excl / LTM / Prior) | L4: Gross profit
A5: BH-39987 | B5: 45444 | C5: C05 | D5: Pioneer Foods Distribution | E5: Grocery | F5: Granola | G5: 3050 | H5: 37.62 | I5: 114741 | J5: 79605 | K5: =IF(OR(COUNTIF($A$5:A5,A5)>1,G5<0,C5="",B5<'Work 1'!$C$6,B5>'Work 1'!$C$7,H5>'Work 1'!$C$8*AVERAGEIF($F$5:$F$1014,F5,$H$5:$H$1014)),"Excl",IF(B5>='Work 1'!$C$5,"LTM","Prior")) | L5: =I5-J5
A6: BH-40001 | B6: 45474 | C6: C01 | D6: Northfield Markets | E6: Grocery | F6: Granola | G6: 11215 | H6: 39.29 | I6: 440637.35 | J6: 292711.5 | K6: =IF(OR(COUNTIF($A$5:A6,A6)>1,G6<0,C6="",B6<'Work 1'!$C$6,B6>'Work 1'!$C$7,H6>'Work 1'!$C$8*AVERAGEIF($F$5:$F$1014,F6,$H$5:$H$1014)),"Excl",IF(B6>='Work 1'!$C$5,"LTM","Prior")) | L6: =I6-J6
A7: BH-40002 | B7: 45474 | C7: C01 | D7: Northfield Markets | E7: Grocery | F7: Nut Butter | G7: 5876 | H7: 52.26 | I7: 307079.76 | J7: 225638.4 | K7: =IF(OR(COUNTIF($A$5:A7,A7)>1,G7<0,C7="",B7<'Work 1'!$C$6,B7>'Work 1'!$C$7,H7>'Work 1'!$C$8*AVERAGEIF($F$5:$F$1014,F7,$H$5:$H$1014)),"Excl",IF(B7>='Work 1'!$C$5,"LTM","Prior")) | L7: =I7-J7
A8: BH-40003 | B8: 45474 | C8: C01 | D8: Northfield Markets | E8: Grocery | F8: Snack Bars | G8: 8762 | H8: 30.46 | I8: 266890.52 | J8: 173487.6 | K8: =IF(OR(COUNTIF($A$5:A8,A8)>1,G8<0,C8="",B8<'Work 1'!$C$6,B8>'Work 1'!$C$7,H8>'Work 1'!$C$8*AVERAGEIF($F$5:$F$1014,F8,$H$5:$H$1014)),"Excl",IF(B8>='Work 1'!$C$5,"LTM","Prior")) | L8: =I8-J8
A9: BH-40004 | B9: 45474 | C9: C02 | D9: Crestline Grocers | E9: Grocery | F9: Granola | G9: 3614 | H9: 40.55 | I9: 146547.7 | J9: 94325.4 | K9: =IF(OR(COUNTIF($A$5:A9,A9)>1,G9<0,C9="",B9<'Work 1'!$C$6,B9>'Work 1'!$C$7,H9>'Work 1'!$C$8*AVERAGEIF($F$5:$F$1014,F9,$H$5:$H$1014)),"Excl",IF(B9>='Work 1'!$C$5,"LTM","Prior")) | L9: =I9-J9
A10: BH-40005 | B10: 45474 | C10: C02 | D10: Crestline Grocers | E10: Grocery | F10: Nut Butter | G10: 1835 | H10: 53.93 | I10: 98961.55 | J10: 70464 | K10: =IF(OR(COUNTIF($A$5:A10,A10)>1,G10<0,C10="",B10<'Work 1'!$C$6,B10>'Work 1'!$C$7,H10>'Work 1'!$C$8*AVERAGEIF($F$5:$F$1014,F10,$H$5:$H$1014)),"Excl",IF(B10>='Work 1'!$C$5,"LTM","Prior")) | L10: =I10-J10
A11: BH-40006 | B11: 45474 | C11: C02 | D11: Crestline Grocers | E11: Grocery | F11: Snack Bars | G11: 3081 | H11: 31.43 | I11: 96835.83 | J11: 61003.8 | K11: =IF(OR(COUNTIF($A$5:A11,A11)>1,G11<0,C11="",B11<'Work 1'!$C$6,B11>'Work 1'!$C$7,H11>'Work 1'!$C$8*AVERAGEIF($F$5:$F$1014,F11,$H$5:$H$1014)),"Excl",IF(B11>='Work 1'!$C$5,"LTM","Prior")) | L11: =I11-J11
A12: BH-40007 | B12: 45474 | C12: C03 | D12: ValuClub Warehouse | E12: Club | F12: Granola | G12: 10209 | H12: 35.9 | I12: 366503.1 | J12: 266454.9 | K12: =IF(OR(COUNTIF($A$5:A12,A12)>1,G12<0,C12="",B12<'Work 1'!$C$6,B12>'Work 1'!$C$7,H12>'Work 1'!$C$8*AVERAGEIF($F$5:$F$1014,F12,$H$5:$H$1014)),"Excl",IF(B12>='Work 1'!$C$5,"LTM","Prior")) | L12: =I12-J12
A13: BH-40008 | B13: 45474 | C13: C03 | D13: ValuClub Warehouse | E13: Club | F13: Snack Bars | G13: 11435 | H13: 27.4 | I13: 313319 | J13: 226413 | K13: =IF(OR(COUNTIF($A$5:A13,A13)>1,G13<0,C13="",B13<'Work 1'!$C$6,B13>'Work 1'!$C$7,H13>'Work 1'!$C$8*AVERAGEIF($F$5:$F$1014,F13,$H$5:$H$1014)),"Excl",IF(B13>='Work 1'!$C$5,"LTM","Prior")) | L13: =I13-J13
A14: BH-40009 | B14: 45474 | C14: C04 | D14: Harvest Lane Co-op | E14: Grocery | F14: Granola | G14: 2457 | H14: 41.8 | I14: 102702.6 | J14: 64127.7 | K14: =IF(OR(COUNTIF($A$5:A14,A14)>1,G14<0,C14="",B14<'Work 1'!$C$6,B14>'Work 1'!$C$7,H14>'Work 1'!$C$8*AVERAGEIF($F$5:$F$1014,F14,$H$5:$H$1014)),"Excl",IF(B14>='Work 1'!$C$5,"LTM","Prior")) | L14: =I14-J14
A15: BH-40010 | B15: 45474 | C15: C04 | D15: Harvest Lane Co-op | E15: Grocery | F15: Nut Butter | G15: 1349 | H15: 55.6 | I15: 75004.4 | J15: 51801.6 | K15: =IF(OR(COUNTIF($A$5:A15,A15)>1,G15<0,C15="",B15<'Work 1'!$C$6,B15>'Work 1'!$C$7,H15>'Work 1'!$C$8*AVERAGEIF($F$5:$F$1014,F15,$H$5:$H$1014)),"Excl",IF(B15>='Work 1'!$C$5,"LTM","Prior")) | L15: =I15-J15
A16: BH-40011 | B16: 45474 | C16: C04 | D16: Harvest Lane Co-op | E16: Grocery | F16: Snack Bars | G16: 1643 | H16: 32.4 | I16: 53233.2 | J16: 32531.4 | K16: =IF(OR(COUNTIF($A$5:A16,A16)>1,G16<0,C16="",B16<'Work 1'!$C$6,B16>'Work 1'!$C$7,H16>'Work 1'!$C$8*AVERAGEIF($F$5:$F$1014,F16,$H$5:$H$1014)),"Excl",IF(B16>='Work 1'!$C$5,"LTM","Prior")) | L16: =I16-J16
... A820: BH-40813 | B820: 46054 | C820: C07 | D820: Bramble Hill Online Store | E820: Online | F820: Nut Butter | G820: 1994 | H820: 64.4 | I820: 128413.6 | J820: 78763 | K820: =IF(OR(COUNTIF($A$5:A820,A820)>1,G820<0,C820="",B820<'Work 1'!$C$6,B820>'Work 1'!$C$7,H820>'Work 1'!$C$8*AVERAGEIF($F$5:$F$1014,F820,$H$5:$H$1014)),"Excl",IF(B820>='Work 1'!$C$5,"LTM","Prior")) | L820: =I820-J820
A821: BH-49538 | B821: 46054 | E821: Online | F821: Nut Butter | G821: 1310 | H821: 64.4 | I821: 84364 | J821: 51745 | K821: =IF(OR(COUNTIF($A$5:A821,A821)>1,G821<0,C821="",B821<'Work 1'!$C$6,B821>'Work 1'!$C$7,H821>'Work 1'!$C$8*AVERAGEIF($F$5:$F$1014,F821,$H$5:$H$1014)),"Excl",IF(B821>='Work 1'!$C$5,"LTM","Prior")) | L821: =I821-J821
A822: BH-40814 | B822: 46054 | C822: C07 | D822: Bramble Hill Online Store | E822: Online | F822: Snack Bars | G822: 2457 | H822: 39.3 | I822: 96560.1 | J822: 50245.65 | K822: =IF(OR(COUNTIF($A$5:A822,A822)>1,G822<0,C822="",B822<'Work 1'!$C$6,B822>'Work 1'!$C$7,H822>'Work 1'!$C$8*AVERAGEIF($F$5:$F$1014,F822,$H$5:$H$1014)),"Excl",IF(B822>='Work 1'!$C$5,"LTM","Prior")) | L822: =I822-J822
A823: BH-40815 | B823: 46054 | C823: C08 | D823: Online Marketplace | E823: Online | F823: Granola | G823: 3686 | H823: 43.47 | I823: 160230.42 | J823: 99337.7 | K823: =IF(OR(COUNTIF($A$5:A823,A823)>1,G823<0,C823="",B823<'Work 1'!$C$6,B823>'Work 1'!$C$7,H823>'Work 1'!$C$8*AVERAGEIF($F$5:$F$1014,F823,$H$5:$H$1014)),"Excl",IF(B823>='Work 1'!$C$5,"LTM","Prior")) | L823: =I823-J823
A824: BH-40816 | B824: 46054 | C824: C08 | D824: Online Marketplace | E824: Online | F824: Nut Butter | G824: 1971 | H824: 56.67 | I824: 111696.57 | J824: 77854.5 | K824: =IF(OR(COUNTIF($A$5:A824,A824)>1,G824<0,C824="",B824<'Work 1'!$C$6,B824>'Work 1'!$C$7,H824>'Work 1'!$C$8*AVERAGEIF($F$5:$F$1014,F824,$H$5:$H$1014)),"Excl",IF(B824>='Work 1'!$C$5,"LTM","Prior")) | L824: =I824-J824
A825: BH-40817 | B825: 46054 | C825: C08 | D825: Online Marketplace | E825: Online | F825: Snack Bars | G825: 3190 | H825: 34.58 | I825: 110310.2 | J825: 65235.5 | K825: =IF(OR(COUNTIF($A$5:A825,A825)>1,G825<0,C825="",B825<'Work 1'!$C$6,B825>'Work 1'!$C$7,H825>'Work 1'!$C$8*AVERAGEIF($F$5:$F$1014,F825,$H$5:$H$1014)),"Excl",IF(B825>='Work 1'!$C$5,"LTM","Prior")) | L825: =I825-J825
A826: BH-40818 | B826: 46054 | C826: C09 | D826: Maple Ridge Grocers | E826: Grocery | F826: Granola | G826: 1582 | H826: 43.05 | I826: 68105.1 | J826: 42634.9 | K826: =IF(OR(COUNTIF($A$5:A826,A826)>1,G826<0,C826="",B826<'Work 1'!$C$6,B826>'Work 1'!$C$7,H826>'Work 1'!$C$8*AVERAGEIF($F$5:$F$1014,F826,$H$5:$H$1014)),"Excl",IF(B826>='Work 1'!$C$5,"LTM","Prior")) | L826: =I826-J826
A827: BH-40819 | B827: 46054 | C827: C09 | D827: Maple Ridge Grocers | E827: Grocery | F827: Snack Bars | G827: 1253 | H827: 33.35 | I827: 41787.55 | J827: 25623.85 | K827: =IF(OR(COUNTIF($A$5:A827,A827)>1,G827<0,C827="",B827<'Work 1'!$C$6,B827>'Work 1'!$C$7,H827>'Work 1'!$C$8*AVERAGEIF($F$5:$F$1014,F827,$H$5:$H$1014)),"Excl",IF(B827>='Work 1'!$C$5,"LTM","Prior")) | L827: =I827-J827
A828: BH-40820 | B828: 46054 | C828: C10 | D828: Lakeshore Foods | E828: Grocery | F828: Granola | G828: 1304 | H828: 43.05 | I828: 56137.2 | J828: 35142.8 | K828: =IF(OR(COUNTIF($A$5:A828,A828)>1,G828<0,C828="",B828<'Work 1'!$C$6,B828>'Work 1'!$C$7,H828>'Work 1'!$C$8*AVERAGEIF($F$5:$F$1014,F828,$H$5:$H$1014)),"Excl",IF(B828>='Work 1'!$C$5,"LTM","Prior")) | L828: =I828-J828
A829: BH-40821 | B829: 46054 | C829: C10 | D829: Lakeshore Foods | E829: Grocery | F829: Nut Butter | G829: 546 | H829: 57.25 | I829: 31258.5 | J829: 21567 | K829: =IF(OR(COUNTIF($A$5:A829,A829)>1,G829<0,C829="",B829<'Work 1'!$C$6,B829>'Work 1'!$C$7,H829>'Work 1'!$C$8*AVERAGEIF($F$5:$F$1014,F829,$H$5:$H$1014)),"Excl",IF(B829>='Work 1'!$C$5,"LTM","Prior")) | L829: =I829-J829
A830: BH-40822 | B830: 46054 | C830: C11 | D830: Copper Valley Market | E830: Grocery | F830: Granola | G830: 1261 | H830: 43.05 | I830: 54286.05 | J830: 33983.95 | K830: =IF(OR(COUNTIF($A$5:A830,A830)>1,G830<0,C830="",B830<'Work 1'!$C$6,B830>'Work 1'!$C$7,H830>'Work 1'!$C$8*AVERAGEIF($F$5:$F$1014,F830,$H$5:$H$1014)),"Excl",IF(B830>='Work 1'!$C$5,"LTM","Prior")) | L830: =I830-J830
A831: BH-40823 | B831: 46054 | C831: C11 | D831: Copper Valley Market | E831: Grocery | F831: Snack Bars | G831: 1314 | H831: 33.35 | I831: 43821.9 | J831: 26871.3 | K831: =IF(OR(COUNTIF($A$5:A831,A831)>1,G831<0,C831="",B831<'Work 1'!$C$6,B831>'Work 1'!$C$7,H831>'Work 1'!$C$8*AVERAGEIF($F$5:$F$1014,F831,$H$5:$H$1014)),"Excl",IF(B831>='Work 1'!$C$5,"LTM","Prior")) | L831: =I831-J831
A832: BH-40824 | B832: 46054 | C832: C12 | D832: Riverbend Grocery | E832: Grocery | F832: Granola | G832: 1705 | H832: 43.05 | I832: 73400.25 | J832: 45949.75 | K832: =IF(OR(COUNTIF($A$5:A832,A832)>1,G832<0,C832="",B832<'Work 1'!$C$6,B832>'Work 1'!$C$7,H832>'Work 1'!$C$8*AVERAGEIF($F$5:$F$1014,F832,$H$5:$H$1014)),"Excl",IF(B832>='Work 1'!$C$5,"LTM","Prior")) | L832: =I832-J832
A833: BH-40825 | B833: 46054 | C833: C12 | D833: Riverbend Grocery | E833: Grocery | F833: Nut Butter | G833: 731 | H833: 57.25 | I833: 41849.75 | J833: 28874.5 | K833: =IF(OR(COUNTIF($A$5:A833,A833)>1,G833<0,C833="",B833<'Work 1'!$C$6,B833>'Work 1'!$C$7,H833>'Work 1'!$C$8*AVERAGEIF($F$5:$F$1014,F833,$H$5:$H$1014)),"Excl",IF(B833>='Work 1'!$C$5,"LTM","Prior")) | L833: =I833-J833
... A1014: BH-41005 | B1014: 46174 | C1014: C19 | D1014: Greenway Markets | E1014: Grocery | F1014: Snack Bars | G1014: 710 | H1014: 33.35 | I1014: 23678.5 | J1014: 14519.5 | K1014: =IF(OR(COUNTIF($A$5:A1014,A1014)>1,G1014<0,C1014="",B1014<'Work 1'!$C$6,B1014>'Work 1'!$C$7,H1014>'Work 1'!$C$8*AVERAGEIF($F$5:$F$1014,F1014,$H$5:$H$1014)),"Excl",IF(B1014>='Work 1'!$C$5,"LTM","Prior")) | L1014: =I1014-J1014

Sheet Work 1
A1: Work 1. Data Pack analysis (INT-05): items 31-40
A2: Exclude the five records listed on Case Exhibits before you answer. Answers in $ millions unless the unit column says %.
A3: Inputs
B4: Dollars per $ million | C4: 1000000
B5: First month of the LTM period | C5: 45839
B6: First month of the Data Pack window | C6: 45474
B7: Last month of the Data Pack window | C7: 46174
B8: Price test: exclude a unit price above this multiple of the product's average price | C8: 5
A10: Item | B10: Answer | C10: Value | D10: Unit
A11: Item 31 | B11: LTM revenue | C11: =SUMIFS('Data Pack'!$I$5:$I$1014,'Data Pack'!$K$5:$K$1014,$C$44)/$C$4 | D11: $ millions
A12: Item 32 | B12: Prior-LTM revenue | C12: =SUMIFS('Data Pack'!$I$5:$I$1014,'Data Pack'!$K$5:$K$1014,$C$45)/$C$4 | D12: $ millions
A13: Item 33 | B13: Net revenue on the records you excluded (a negative record counts as negative) | C13: =SUMIFS('Data Pack'!$I$5:$I$1014,'Data Pack'!$K$5:$K$1014,$C$46)/$C$4 | D13: $ millions
A14: Item 34 | B14: LTM gross margin | C14: =(SUMIFS('Data Pack'!$I$5:$I$1014,'Data Pack'!$K$5:$K$1014,$C$44)-SUMIFS('Data Pack'!$J$5:$J$1014,'Data Pack'!$K$5:$K$1014,$C$44))/SUMIFS('Data Pack'!$I$5:$I$1014,'Data Pack'!$K$5:$K$1014,$C$44) | D14: %
A15: Item 35 | B15: Largest customer's share of LTM revenue | C15: =MAX($C$25:$C$43)/SUM($C$25:$C$43) | D15: %
A16: Item 36 | B16: Largest customer's share of prior-LTM revenue | C16: =INDEX($D$25:$D$43,MATCH($C$50,$A$25:$A$43,0))/SUM($D$25:$D$43) | D16: %
A17: Item 37 | B17: Largest customer's LTM gross margin | C17: =INDEX($F$25:$F$43,MATCH($C$50,$A$25:$A$43,0)) | D17: %
A18: Item 38 | B18: Churned revenue: prior-LTM revenue from customers with no LTM revenue | C18: =SUMPRODUCT(--NOT($C$25:$C$43),$D$25:$D$43)/$C$4 | D18: $ millions
A19: Item 39 | B19: ValuClub Warehouse, Snack Bars: change in net price per case, LTM vs prior LTM | C19: =(SUMIFS('Data Pack'!$I$5:$I$1014,'Data Pack'!$D$5:$D$1014,$C$47,'Data Pack'!$F$5:$F$1014,$C$48,'Data Pack'!$K$5:$K$1014,$C$44)/SUMIFS('Data Pack'!$G$5:$G$1014,'Data Pack'!$D$5:$D$1014,$C$47,'Data Pack'!$F$5:$F$1014,$C$48,'Data Pack'!$K$5:$K$1014,$C$44)-SUMIFS('Data Pack'!$I$5:$I$1014,'Data Pack'!$D$5:$D$1014,$C$47,'Data Pack'!$F$5:$F$1014,$C$48,'Data Pack'!$K$5:$K$1014,$C$45)/SUMIFS('Data Pack'!$G$5:$G$1014,'Data Pack'!$D$5:$D$1014,$C$47,'Data Pack'!$F$5:$F$1014,$C$48,'Data Pack'!$K$5:$K$1014,$C$45))/(SUMIFS('Data Pack'!$I$5:$I$1014,'Data Pack'!$D$5:$D$1014,$C$47,'Data Pack'!$F$5:$F$1014,$C$48,'Data Pack'!$K$5:$K$1014,$C$45)/SUMIFS('Data Pack'!$G$5:$G$1014,'Data Pack'!$D$5:$D$1014,$C$47,'Data Pack'!$F$5:$F$1014,$C$48,'Data Pack'!$K$5:$K$1014,$C$45)) | D19: %
A20: Item 40 | B20: Crestline Grocers: LTM gross profit | C20: =(SUMIFS('Data Pack'!$I$5:$I$1014,'Data Pack'!$D$5:$D$1014,$C$49,'Data Pack'!$K$5:$K$1014,$C$44)-SUMIFS('Data Pack'!$J$5:$J$1014,'Data Pack'!$D$5:$D$1014,$C$49,'Data Pack'!$K$5:$K$1014,$C$44))/$C$4 | D20: $ millions
A22: Work area
A23: Build your cuts here or in helper columns on the Data Pack.
A24: Customer ID | B24: Customer | C24: LTM revenue ($) | D24: Prior-LTM revenue ($) | E24: LTM COGS ($) | F24: LTM gross margin
A25: C01 | B25: =INDEX('Data Pack'!$D$5:$D$1014,MATCH(A25,'Data Pack'!$C$5:$C$1014,0)) | C25: =SUMIFS('Data Pack'!$I$5:$I$1014,'Data Pack'!$C$5:$C$1014,A25,'Data Pack'!$K$5:$K$1014,$C$44) | D25: =SUMIFS('Data Pack'!$I$5:$I$1014,'Data Pack'!$C$5:$C$1014,A25,'Data Pack'!$K$5:$K$1014,$C$45) | E25: =SUMIFS('Data Pack'!$J$5:$J$1014,'Data Pack'!$C$5:$C$1014,A25,'Data Pack'!$K$5:$K$1014,$C$44) | F25: =IFERROR((C25-E25)/C25,"n/a")
A26: C02 | B26: =INDEX('Data Pack'!$D$5:$D$1014,MATCH(A26,'Data Pack'!$C$5:$C$1014,0)) | C26: =SUMIFS('Data Pack'!$I$5:$I$1014,'Data Pack'!$C$5:$C$1014,A26,'Data Pack'!$K$5:$K$1014,$C$44) | D26: =SUMIFS('Data Pack'!$I$5:$I$1014,'Data Pack'!$C$5:$C$1014,A26,'Data Pack'!$K$5:$K$1014,$C$45) | E26: =SUMIFS('Data Pack'!$J$5:$J$1014,'Data Pack'!$C$5:$C$1014,A26,'Data Pack'!$K$5:$K$1014,$C$44) | F26: =IFERROR((C26-E26)/C26,"n/a")
A27: C03 | B27: =INDEX('Data Pack'!$D$5:$D$1014,MATCH(A27,'Data Pack'!$C$5:$C$1014,0)) | C27: =SUMIFS('Data Pack'!$I$5:$I$1014,'Data Pack'!$C$5:$C$1014,A27,'Data Pack'!$K$5:$K$1014,$C$44) | D27: =SUMIFS('Data Pack'!$I$5:$I$1014,'Data Pack'!$C$5:$C$1014,A27,'Data Pack'!$K$5:$K$1014,$C$45) | E27: =SUMIFS('Data Pack'!$J$5:$J$1014,'Data Pack'!$C$5:$C$1014,A27,'Data Pack'!$K$5:$K$1014,$C$44) | F27: =IFERROR((C27-E27)/C27,"n/a")
A28: C04 | B28: =INDEX('Data Pack'!$D$5:$D$1014,MATCH(A28,'Data Pack'!$C$5:$C$1014,0)) | C28: =SUMIFS('Data Pack'!$I$5:$I$1014,'Data Pack'!$C$5:$C$1014,A28,'Data Pack'!$K$5:$K$1014,$C$44) | D28: =SUMIFS('Data Pack'!$I$5:$I$1014,'Data Pack'!$C$5:$C$1014,A28,'Data Pack'!$K$5:$K$1014,$C$45) | E28: =SUMIFS('Data Pack'!$J$5:$J$1014,'Data Pack'!$C$5:$C$1014,A28,'Data Pack'!$K$5:$K$1014,$C$44) | F28: =IFERROR((C28-E28)/C28,"n/a")
A29: C05 | B29: =INDEX('Data Pack'!$D$5:$D$1014,MATCH(A29,'Data Pack'!$C$5:$C$1014,0)) | C29: =SUMIFS('Data Pack'!$I$5:$I$1014,'Data Pack'!$C$5:$C$1014,A29,'Data Pack'!$K$5:$K$1014,$C$44) | D29: =SUMIFS('Data Pack'!$I$5:$I$1014,'Data Pack'!$C$5:$C$1014,A29,'Data Pack'!$K$5:$K$1014,$C$45) | E29: =SUMIFS('Data Pack'!$J$5:$J$1014,'Data Pack'!$C$5:$C$1014,A29,'Data Pack'!$K$5:$K$1014,$C$44) | F29: =IFERROR((C29-E29)/C29,"n/a")
A30: C06 | B30: =INDEX('Data Pack'!$D$5:$D$1014,MATCH(A30,'Data Pack'!$C$5:$C$1014,0)) | C30: =SUMIFS('Data Pack'!$I$5:$I$1014,'Data Pack'!$C$5:$C$1014,A30,'Data Pack'!$K$5:$K$1014,$C$44) | D30: =SUMIFS('Data Pack'!$I$5:$I$1014,'Data Pack'!$C$5:$C$1014,A30,'Data Pack'!$K$5:$K$1014,$C$45) | E30: =SUMIFS('Data Pack'!$J$5:$J$1014,'Data Pack'!$C$5:$C$1014,A30,'Data Pack'!$K$5:$K$1014,$C$44) | F30: =IFERROR((C30-E30)/C30,"n/a")
A31: C07 | B31: =INDEX('Data Pack'!$D$5:$D$1014,MATCH(A31,'Data Pack'!$C$5:$C$1014,0)) | C31: =SUMIFS('Data Pack'!$I$5:$I$1014,'Data Pack'!$C$5:$C$1014,A31,'Data Pack'!$K$5:$K$1014,$C$44) | D31: =SUMIFS('Data Pack'!$I$5:$I$1014,'Data Pack'!$C$5:$C$1014,A31,'Data Pack'!$K$5:$K$1014,$C$45) | E31: =SUMIFS('Data Pack'!$J$5:$J$1014,'Data Pack'!$C$5:$C$1014,A31,'Data Pack'!$K$5:$K$1014,$C$44) | F31: =IFERROR((C31-E31)/C31,"n/a")
A32: C08 | B32: =INDEX('Data Pack'!$D$5:$D$1014,MATCH(A32,'Data Pack'!$C$5:$C$1014,0)) | C32: =SUMIFS('Data Pack'!$I$5:$I$1014,'Data Pack'!$C$5:$C$1014,A32,'Data Pack'!$K$5:$K$1014,$C$44) | D32: =SUMIFS('Data Pack'!$I$5:$I$1014,'Data Pack'!$C$5:$C$1014,A32,'Data Pack'!$K$5:$K$1014,$C$45) | E32: =SUMIFS('Data Pack'!$J$5:$J$1014,'Data Pack'!$C$5:$C$1014,A32,'Data Pack'!$K$5:$K$1014,$C$44) | F32: =IFERROR((C32-E32)/C32,"n/a")
A33: C09 | B33: =INDEX('Data Pack'!$D$5:$D$1014,MATCH(A33,'Data Pack'!$C$5:$C$1014,0)) | C33: =SUMIFS('Data Pack'!$I$5:$I$1014,'Data Pack'!$C$5:$C$1014,A33,'Data Pack'!$K$5:$K$1014,$C$44) | D33: =SUMIFS('Data Pack'!$I$5:$I$1014,'Data Pack'!$C$5:$C$1014,A33,'Data Pack'!$K$5:$K$1014,$C$45) | E33: =SUMIFS('Data Pack'!$J$5:$J$1014,'Data Pack'!$C$5:$C$1014,A33,'Data Pack'!$K$5:$K$1014,$C$44) | F33: =IFERROR((C33-E33)/C33,"n/a")
A34: C10 | B34: =INDEX('Data Pack'!$D$5:$D$1014,MATCH(A34,'Data Pack'!$C$5:$C$1014,0)) | C34: =SUMIFS('Data Pack'!$I$5:$I$1014,'Data Pack'!$C$5:$C$1014,A34,'Data Pack'!$K$5:$K$1014,$C$44) | D34: =SUMIFS('Data Pack'!$I$5:$I$1014,'Data Pack'!$C$5:$C$1014,A34,'Data Pack'!$K$5:$K$1014,$C$45) | E34: =SUMIFS('Data Pack'!$J$5:$J$1014,'Data Pack'!$C$5:$C$1014,A34,'Data Pack'!$K$5:$K$1014,$C$44) | F34: =IFERROR((C34-E34)/C34,"n/a")
A35: C11 | B35: =INDEX('Data Pack'!$D$5:$D$1014,MATCH(A35,'Data Pack'!$C$5:$C$1014,0)) | C35: =SUMIFS('Data Pack'!$I$5:$I$1014,'Data Pack'!$C$5:$C$1014,A35,'Data Pack'!$K$5:$K$1014,$C$44) | D35: =SUMIFS('Data Pack'!$I$5:$I$1014,'Data Pack'!$C$5:$C$1014,A35,'Data Pack'!$K$5:$K$1014,$C$45) | E35: =SUMIFS('Data Pack'!$J$5:$J$1014,'Data Pack'!$C$5:$C$1014,A35,'Data Pack'!$K$5:$K$1014,$C$44) | F35: =IFERROR((C35-E35)/C35,"n/a")
A36: C12 | B36: =INDEX('Data Pack'!$D$5:$D$1014,MATCH(A36,'Data Pack'!$C$5:$C$1014,0)) | C36: =SUMIFS('Data Pack'!$I$5:$I$1014,'Data Pack'!$C$5:$C$1014,A36,'Data Pack'!$K$5:$K$1014,$C$44) | D36: =SUMIFS('Data Pack'!$I$5:$I$1014,'Data Pack'!$C$5:$C$1014,A36,'Data Pack'!$K$5:$K$1014,$C$45) | E36: =SUMIFS('Data Pack'!$J$5:$J$1014,'Data Pack'!$C$5:$C$1014,A36,'Data Pack'!$K$5:$K$1014,$C$44) | F36: =IFERROR((C36-E36)/C36,"n/a")
... A43: C19 | B43: =INDEX('Data Pack'!$D$5:$D$1014,MATCH(A43,'Data Pack'!$C$5:$C$1014,0)) | C43: =SUMIFS('Data Pack'!$I$5:$I$1014,'Data Pack'!$C$5:$C$1014,A43,'Data Pack'!$K$5:$K$1014,$C$44) | D43: =SUMIFS('Data Pack'!$I$5:$I$1014,'Data Pack'!$C$5:$C$1014,A43,'Data Pack'!$K$5:$K$1014,$C$45) | E43: =SUMIFS('Data Pack'!$J$5:$J$1014,'Data Pack'!$C$5:$C$1014,A43,'Data Pack'!$K$5:$K$1014,$C$44) | F43: =IFERROR((C43-E43)/C43,"n/a")
B44: Period label: LTM | C44: LTM
B45: Period label: prior LTM | C45: Prior
B46: Period label: excluded records | C46: Excl
B47: Customer for item 39 | C47: ValuClub Warehouse
B48: Product for item 39 | C48: Snack Bars
...

Sheet Work 2
A1: Work 2. Underwriting EBITDA (INT-05, INT-21): items 41-48
A2: Choose a treatment for each line and write a one-line reason that cites the diligence note. Fill column D with formulas. $ millions.
A4: Line | B4: Amount | C4: Treatment | D4: Included | E4: Reason (one line) | F4: Item
A5: Reported EBITDA, LTM | B5: ='Case Exhibits'!$B$16 | D5: =B5
A6: Founder compensation above market | B6: ='Case Exhibits'!$B$17 | C6: Accept | D6: =IF(C6="Accept",B6,IF(C6="Haircut",B6*$B$16,0)) | E6: Accept: founder is paid 1.10, retires at close, and the 0.65 add-back is already net of the 0.45 replacement CEO cost, so it will not recur. | F6: Item 41
A7: Co-packer litigation settlement | B7: ='Case Exhibits'!$B$18 | C7: Accept | D7: =IF(C7="Accept",B7,IF(C7="Haircut",B7*$B$16,0)) | E7: Accept: counsel confirms one dispute with a former co-packer, settled in the LTM period, with no other open claims, so it is non-recurring. | F7: Item 42
A8: Second-line start-up costs | B8: ='Case Exhibits'!$B$19 | C8: Haircut | D8: =IF(C8="Accept",B8,IF(C8="Haircut",B8*$B$16,0)) | E8: Haircut: the line is at 70% utilization and scrap is only expected to settle over two quarters, so part of the 0.60 will recur. | F8: Item 43
A9: Pro forma list-price increase | B9: ='Case Exhibits'!$B$20 | C9: Reject | D9: =IF(C9="Accept",B9,IF(C9="Haircut",B9*$B$16,0)) | E9: Reject: the 8% list-price increase was announced after the LTM period and no customer has accepted it, so the benefit is not agreed. | F9: Item 44
A10: New-product slotting fees | B10: ='Case Exhibits'!$B$21 | C10: Reject | D10: =IF(C10="Accept",B10,IF(C10="Haircut",B10*$B$16,0)) | E10: Reject: the company has launched new items in each of the last four years, so slotting fees and launch promotions recur every year. | F10: Item 45
A11: Freight contract savings | B11: ='Case Exhibits'!$B$22 | C11: Haircut | D11: =IF(C11="Accept",B11,IF(C11="Haircut",B11*$B$16,0)) | E11: Haircut: the freight contract is signed but only one month of savings is in reported EBITDA, so eleven months are not yet in results. | F11: Item 46
A12: Crestline Grocers: LTM gross profit (Work 1, item 40) | B12: ='Work 1'!C20 | C12: Deduct | D12: =IF(C12="Deduct",-B12,0) | E12: Deduct: Crestline Grocers gave written notice after the LTM period that it will not renew, so its LTM gross profit will not recur. | F12: Item 47
A13: Underwriting EBITDA, LTM | D13: =SUM(D5:D12) | F13: Item 48
A16: Haircut inclusion % (Case Exhibits) | B16: ='Case Exhibits'!$B$24
A18: Treatment rules
A19: Accept: a documented cost that will not recur after close. Include 100%.
A20: Haircut: a saving that is contracted but not yet in a full year of results, or a cost of which part will recur. Include the haircut inclusion %.
A21: Reject: the benefit depends on something not yet agreed or started, or the cost recurs every year. Include 0%.
A22: Lost customer: Deduct the LTM gross profit of a customer that has given notice. Otherwise Ignore.
A23: Enter deductions as negative numbers in column D. Underwriting EBITDA = the sum of column D.

Sheet Work 3
A1: Work 3. Sources and uses, debt schedule and returns (INT-01 to INT-04): items 49-64
A2: Fill every yellow cell with a formula. $ millions. Year 0 is the close at the end of the LTM period. The downside block uses the Downside inputs in column D. Price and debt are sized on management's EBITDA (C32); the projection starts from your underwriting EBITDA (C33).
A4: Item | B4: Answer | C4: Value | D4: Unit
A5: Item 49 | B5: Purchase enterprise value | C5: =C50 | D5: $ millions
A6: Item 50 | B6: Total fees | C6: =C53 | D6: $ millions
A7: Item 51 | B7: Total uses | C7: =C55 | D7: $ millions
A8: Item 52 | B8: Term loan B | C8: =C56 | D8: $ millions
A9: Item 53 | B9: Seller note | C9: =C57 | D9: $ millions
A10: Item 54 | B10: Sponsor equity | C10: =C58 | D10: $ millions
A11: Item 55 | B11: Goodwill created at close | C11: =C60 | D11: $ millions
A12: Item 56 | B12: Entry multiple on your underwriting EBITDA | C12: =C61 | D12: x
A13: Item 57 | B13: Base case, Year 1 cash interest (term loan B + commitment fee) | C13: =E75 | D13: $ millions
A14: Item 58 | B14: Base case, Year 3 term loan B ending balance | C14: =G72 | D14: $ millions
A15: Item 59 | B15: Base case, exit equity value | C15: =D88 | D15: $ millions
A16: Item 60 | B16: Base case, MOIC | C16: =D89 | D16: x
A17: Item 61 | B17: Base case, IRR | C17: =D90 | D17: %
A18: Item 62 | B18: Downside case, MOIC | C18: =D118 | D18: x
A19: Item 63 | B19: Downside case, IRR | C19: =D119 | D19: %
A20: Item 64 | B20: Data Table: base IRR at a 9.0x exit in Year 6 | C20: =H126 | D20: %
B22: Projection inputs | C22: Base | D22: Downside
B23: Year 1 EBITDA growth | C23: 0.08 | D23: -0.05
B24: EBITDA growth, Years 2-6 | C24: 0.08 | D24: 0.04
B25: Capex, % of EBITDA | C25: 0.25 | D25: 0.25
B26: Increase in net working capital, per year | C26: 0.3 | D26: 0.4
B27: Exit multiple | C27: 8 | D27: 7
B28: Exit year | C28: 5 | D28: 6
B29: Interest toggle, both cases: 1 = average balance, 0 = opening balance. Leave at 1 when you submit. | C29: 1
B31: Links | C31: Value
B32: Management Adjusted EBITDA | C32: ='Case Exhibits'!$B$23
B33: Underwriting EBITDA (Work 2, item 48) | C33: ='Work 2'!D13
B34: Bid multiple | C34: ='Case Exhibits'!$B$37
B35: Advisory and other fees, % of EV | C35: ='Case Exhibits'!$B$38
B36: Financing fees, % of term loan B | C36: ='Case Exhibits'!$B$39
B37: Minimum cash | C37: ='Case Exhibits'!$B$40
B38: Fair value of net identifiable assets | C38: ='Case Exhibits'!$B$41
B39: Term loan B, multiple of Management Adjusted EBITDA | C39: ='Case Exhibits'!$B$42
B40: Term loan B all-in rate | C40: ='Case Exhibits'!$B$45
B41: Mandatory amortization, % of original | C41: ='Case Exhibits'!$B$46
B42: Revolver commitment | C42: ='Case Exhibits'!$B$47
B43: Commitment fee on undrawn revolver | C43: ='Case Exhibits'!$B$48
...

Sheet Work 4
A1: Work 4. Credit solvency, pro forma at close on LTM (INT-08 to INT-12): items 65-77
A2: Use your underwriting EBITDA from Work 2 and the closing debt from Work 3. $ millions.
A4: Item | B4: Answer | C4: Value | D4: Unit
A5: Item 65 | B5: Pro forma cash interest | C5: =C23*C25+C26*C27 | D5: $ millions
A6: Item 66 | B6: Pro forma cash taxes | C6: =MAX(C31*(C22-C30-C5-C24*C28),0) | D6: $ millions
A7: Item 67 | B7: Increase in net working capital, LTM | C7: =('Case Exhibits'!C27+'Case Exhibits'!C28+'Case Exhibits'!C29-'Case Exhibits'!C30-'Case Exhibits'!C31)-('Case Exhibits'!B27+'Case Exhibits'!B28+'Case Exhibits'!B29-'Case Exhibits'!B30-'Case Exhibits'!B31) | D7: $ millions
A8: Item 68 | B8: Levered free cash flow: EBITDA - cash interest - cash taxes - capex - increase in NWC | C8: =C22-C5-C6-C29-C7 | D8: $ millions
A9: Item 69 | B9: Mandatory amortization | C9: =C32*C23 | D9: $ millions
A10: Item 70 | B10: Cash available for discretionary repayment | C10: =C8-C9 | D10: $ millions
A11: Item 71 | B11: Total debt (term loan B + seller note) / underwriting EBITDA | C11: =(C23+C24)/C22 | D11: x
A12: Item 72 | B12: Interest coverage: EBITDA / cash interest | C12: =C22/C5 | D12: x
A13: Item 73 | B13: Cash coverage: (EBITDA - capex) / cash interest | C13: =(C22-C29)/C5 | D13: x
A14: Item 74 | B14: Fixed-charge coverage: (EBITDA - capex - cash taxes) / (cash interest + mandatory amortization) | C14: =(C22-C29-C6)/(C5+C9) | D14: x
A15: Item 75 | B15: EBITDA cushion: % by which underwriting EBITDA can fall before total net leverage (term loan B + seller note - minimum cash) reaches the covenant maximum | C15: =(C22-(C23+C24-C33)/C34)/C22 | D15: %
A16: Item 76 | B16: Debt capacity from the lender's downside coverage test | C16: =(C22-C22*C35)/C36/C25 | D16: $ millions
A17: Item 77 | B17: Debt at close (term loan B + seller note) above the governing debt capacity | C17: =C23+C24-C41 | D17: $ millions
B21: Links | C21: Value
B22: Underwriting EBITDA (Work 2, item 48) | C22: ='Work 2'!D13
B23: Term loan B at close (Work 3) | C23: ='Work 3'!C56
B24: Seller note at close (Work 3) | C24: ='Work 3'!C57
B25: Term loan B all-in rate | C25: ='Case Exhibits'!$B$45
B26: Revolver commitment | C26: ='Case Exhibits'!$B$47
B27: Commitment fee on undrawn revolver | C27: ='Case Exhibits'!$B$48
B28: Seller note PIK rate | C28: ='Case Exhibits'!$B$50
B29: LTM capital expenditures | C29: ='Case Exhibits'!$B$32
B30: LTM depreciation and amortization | C30: ='Case Exhibits'!$B$33
B31: Cash tax rate | C31: ='Case Exhibits'!$B$34
B32: Mandatory amortization, % of original | C32: ='Case Exhibits'!$B$46
B33: Minimum cash | C33: ='Case Exhibits'!$B$40
B34: Covenant: maximum total net leverage | C34: ='Case Exhibits'!$B$51
B35: Lender downside test: EBITDA decline | C35: ='Case Exhibits'!$B$52
B36: Lender downside test: minimum EBITDA / interest (debt x all-in rate) | C36: ='Case Exhibits'!$B$53
B38: Debt capacity | C38: Value
B39: Comparable transactions: median total debt / EBITDA | C39: =MEDIAN('Case Exhibits'!C59:C64)
B40: Market debt capacity | C40: =C39*C22
B41: Governing debt capacity: the lower of market capacity and item 76 | C41: =MIN(C40,C16)

Sheet Work 5
A1: Work 5. Recovery waterfall, Kestrel Bakeries (INT-11): items 78-81
A2: A different borrower, in a restructuring. $ millions.
A4: Item | B4: Answer | C4: Value | D4: Unit
A5: Item 78 | B5: First lien: recovery from collateral | C5: =MIN(C14,MAX(C12-C13,0)) | D5: $ millions
A6: Item 79 | B6: First lien: deficiency claim | C6: =C14-C5 | D6: $ millions
A7: Item 80 | B7: Unsecured pool: recovery rate | C7: =(C11-C12)/C22 | D7: %
A8: Item 81 | B8: First lien: total recovery rate | C8: =(C5+C6*C7)/C14 | D8: %
B10: Inputs | C10: Value
B11: Value available for distribution | C11: 47
B12: Collateral value | C12: 26
B13: Revolver claim (paid first from collateral) | C13: 6
B14: First lien claim | C14: 28
B15: Second lien claim (same collateral, junior to the first lien) | C15: 15
B16: Unsecured claims | C16: 9
B17: Collateral pays the revolver, then the first lien, then the second lien. Value above the collateral goes pro rata to all unsecured claims, including deficiency claims.
B19: Work area | C19: Value
B20: Second lien: recovery from collateral | C20: =MIN(C15,MAX(C12-C13-C5,0))
B21: Second lien: deficiency claim | C21: =C15-C20
B22: Unsecured pool: total claims | C22: =C16+C6+C21

Sheet Work 6
A1: Work 6. Real estate and cross-asset comparison (INT-16, INT-17): items 82-87
A2: Alder Court Apartments: whole dollars. Private credit: rates.
A4: Item | B4: Answer | C4: Value | D4: Unit
A5: Item 82 | B5: Effective gross revenue | C5: =C46-C46*C15+C16 | D5: $
A6: Item 83 | B6: Net operating income | C6: =C5-C48 | D6: $
A7: Item 84 | B7: Debt service coverage ratio | C7: =C6/C49 | D7: x
A8: Item 85 | B8: Cash-on-cash return: (NOI - annual debt service) / equity invested | C8: =(C6-C49)/C50 | D8: %
A9: Item 86 | B9: Private credit all-in yield | C9: =C33+C34+C35/C36 | D9: %
A10: Item 87 | B10: Which seats clear their own hurdle? (PE = the buyout, PC = the unitranche loan, RE = the property) | C10: PC only | D10: choose
B12: Alder Court Apartments: operating statement inputs | C12: Value
B13: Units | C13: 40
B14: Market rent per unit per month | C14: 1725
B15: Vacancy and credit loss, % of potential gross revenue (rent only; add other income after vacancy) | C15: 0.06
B16: Other income (parking, laundry), per year | C16: 24000
B17: Operating expense: Real estate taxes | C17: 96000
B18: Operating expense: Insurance | C18: 38000
B19: Operating expense: Recurring repairs and maintenance | C19: 52000
B20: Operating expense: Utilities | C20: 41000
B21: Operating expense: On-site payroll | C21: 64000
B22: Property management fee, % of effective gross revenue | C22: 0.04
B23: Seller's operating statement, last year: Roof replacement (one-time) | C23: 85000
B24: Seller's operating statement, last year: Unit renovation capital expenditures | C24: 120000
... B30: Months per year | C30: 12
B32: Private credit: Unitranche loan to a software distributor | C32: Value
B33: SOFR | C33: 0.0425
B34: Spread | C34: 0.055
B35: Original issue discount (OID), % of par | C35: 0.02
B36: Expected life, years | C36: 4
B37: All-in yield = SOFR + spread + OID / expected life.
B39: Hurdles and the buyout | C39: Value
B40: Private equity hurdle: IRR | C40: 0.2
B41: Private credit hurdle: all-in yield | C41: 0.095
B42: Real estate hurdle: cash-on-cash return | C42: 0.06
B43: Project Bramble base-case IRR (Work 3, item 61) | C43: ='Work 3'!D90
B45: Work area | C45: Value
B46: Potential gross revenue (rent at full occupancy) | C46: =C13*C14*C30
B47: Property management fee | C47: =C22*C5
B48: Total operating expenses | C48: =C17+C18+C19+C20+C21+C47
B49: Annual debt service | C49: =-PMT(C28/C30,C29*C30,C27)*C30
B50: Equity invested (price + closing costs - loan) | C50: =C25+C26*C25-C27

Sheet Work 7
A1: Work 7. Self-audit of a prior analyst's Model Output page (INT-21): items 88-99
A2: This is another analyst's draft at the first-round bid, with its own figures; do not compare it with your Work tabs. Click each value to read its formula. Judge each line on its own formula and value; a line that only inherits another line's error is OK. Choose a finding for every line. Write a fix for every line you do not mark OK.
B4: Page inputs: prior analyst's draft, first-round bid | C4: Value
B5: Management Adjusted EBITDA | C5: 10.85
B6: First-round bid multiple | C6: 7.4
B7: Total fees | C7: 2.8
B8: Minimum cash | C8: 2
B9: Term loan B | C9: 45
B10: Seller note | C10: 4
B11: Sponsor equity | C11: 34.59
B12: Fair value of net identifiable assets | C12: 24
B13: Reported EBITDA, LTM | C13: 7.6
B14: Add-backs accepted | C14: 1.95
B15: Lost-customer deduction | C15: -1.4
B16: Year 1 EBITDA | C16: 8.5
... B20: Year 1 seller note PIK interest | C20: 0.32
B21: Year 1 taxable income (tax schedule) | C21: =C16-C19-C9*C17-C18-C20
B22: Cash tax rate | C22: 0.25
B23: Year 1 capital expenditures | C23: 2.55
B24: Year 1 increase in net working capital | C24: 0.3
B25: Base-case MOIC (scenario run) | C25: 1.94
B26: Holding period, years | C26: 5
B27: Base-case IRR (scenario run) | C27: 0.142
B28: Downside IRR (scenario run) | C28: 0.131
B29: Exit multiple | C29: 9.5
B30: Mandatory amortization, % of original | C30: 0.01
B32: Backup: EBITDA bridge | C32: Value
B33: Reported EBITDA | C33: =C13
B34: Add-backs accepted | C34: =C14
B35: Lost-customer deduction | C35: =C15
B36: Underwriting EBITDA per bridge | C36: =SUM(C33:C35)
B38: Context (not scored) | C38: Value
B39: Purchase enterprise value | C39: =C6*C5
B40: Total uses | C40: =C39+C7+C8
B41: Entry multiple (first-round bid) | C41: =C6
A43: Line | B43: Model Output page | C43: Value | D43: Finding | E43: Fix
A44: L1 | B44: Total leverage at close (total debt / underwriting EBITDA) | C44: =(C9+C10)/C36 | D44: OK
A45: L2 | B45: Total sources vs total uses (compare with total uses) | C45: =C9+C10+C11 | D45: Does not foot | E45: Sources are 83.59 against total uses of 85.09 (C40), a 1.50 gap; re-plug sponsor equity to 36.09 so sources equal uses.
A46: L3 | B46: Underwriting EBITDA on the summary line (compare with the backup) | C46: =C13+C14 | D46: Mismatch with backup | E46: Summary shows 9.55 (=C13+C14) but the backup bridge gives 8.15; link to C36 so the 1.40 lost-customer deduction is included.
A47: L4 | B47: Goodwill created at close | C47: =C39-C12 | D47: OK
...

Sheet Synthesis
A1: Synthesis: your view on Project Bramble (INT-06, INT-13, INT-18 to INT-20)
A2: Two to four sentences per prompt. Cite figures from your Work tabs. 2 points each.
B4: Prompt | C4: Your answer
A5: S1 | B5: Recommendation on the deal as bid. Choose Proceed, Pass, or Proceed with conditions, then give two sentences of reasons. | C5: Pass at the bid as structured (the alternative is to re-bid lower). The 6.75x bid on management's 10.85 EBITDA is 9.71x my underwriting EBITDA of 7.54, and the base case returns only an 11.4% IRR and 1.72x MOIC (Work 3), well under the 20% hurdle. Total debt of 5.52x also sits above debt capacity, so the structure does not work at this price.
A6: S2 | B6: Name the single largest solvency risk. Cite one figure from Work 1, Work 2 or Work 4. | C6: The largest solvency risk is too much debt on a lower real EBITDA: debt at close is 41.6 (5.52x underwriting EBITDA), which is 8.8 above the governing debt capacity of 32.8 (Work 4, item 77). Fixed-charge coverage is only 1.23x and cash available for discretionary repayment is just 0.33 after mandatory amortization, so there is almost no cushion if EBITDA slips or Crestline (1.61 of LTM gross profit) is lost.
A7: S3 | B7: Give the strongest protection against that risk and explain why it would still hold if the risk happens. | C7: The strongest protection is to cut debt at close to the governing capacity (about 32.8) and replace the difference with sponsor equity or a price cut. This still holds if the risk happens because lower fixed charges do not depend on EBITDA, and the lender's downside test (EBITDA down 20%, coverage at least 2.0x) is met by design rather than by a forecast. A contracted replacement for Crestline would add support but is not yet agreed.
A8: S4 | B8: Justify or reject the entry price against the comparable transactions. Cite the multiple on your underwriting EBITDA. | C8: I reject the entry price. At 6.75x management EBITDA the purchase enterprise value is 73.2, or 9.71x my underwriting EBITDA of 7.54, against a comparable median of 8.3x EV/EBITDA (range 7.6x to 9.3x), so we pay above even the top comp, Northbeam at 9.3x. A price of about 8.3x on 7.54 would be about 62.6, roughly 10.6 lower.
A9: S5 | B9: Say what the downside case changed in your recommendation. Cite the downside MOIC or IRR. | C9: The downside case (growth of -5% in Year 1, 7.0x exit, Year 6) returns 0.85x MOIC and a -2.7% IRR (Work 3), so equity loses money, whereas the base case already misses the hurdle at 11.4%. This moved my view from a possible re-price to a firm Pass at this price and leverage. I would only re-engage with lower debt, a lower price, and a signed replacement for Crestline.
B11: Scoring: each answer names the driver, cites a correct figure from your workbook, and states what it means for the deal or the credit.

Sheet Self-Check
A1: Self-Check: run this before you save
A2: Every line must read OK. A line that reads CHECK names what to fix.
B4: Check | C4: Status
A5: 1 | B5: Your name and cohort are filled in on Read Me. | C5: =IF(AND(FELLOW_NAME<>"",FELLOW_COHORT<>""),"OK","CHECK") | G5: Work 1!C11 | H5: =--NOT(ISNA(FORMULATEXT('Work 1'!C11))) | I5: =IFERROR(SUMPRODUCT((CODE(MID(SUBSTITUTE(SUBSTITUTE(FORMULATEXT('Work 1'!C11),"$",""),"Work ","Work"),ROW($Z$1:$Z$700),1)&" ")>47)*(CODE(MID(SUBSTITUTE(SUBSTITUTE(FORMULATEXT('Work 1'!C11),"$",""),"Work ","Work"),ROW($Z$1:$Z$700),1)&" ")<58)*(1-(CODE(MID(" "&SUBSTITUTE(SUBSTITUTE(FORMULATEXT('Work 1'!C11),"$",""),"Work ","Work"),ROW($Z$1:$Z$700),1)&" ")>47)*(CODE(MID(" "&SUBSTITUTE(SUBSTITUTE(FORMULATEXT('Work 1'!C11),"$",""),"Work ","Work"),ROW($Z$1:$Z$700),1)&" ")<58))*EXACT(UPPER(MID(" "&SUBSTITUTE(SUBSTITUTE(FORMULATEXT('Work 1'!C11),"$",""),"Work ","Work"),ROW($Z$1:$Z$700),1)),LOWER(MID(" "&SUBSTITUTE(SUBSTITUTE(FORMULATEXT('Work 1'!C11),"$",""),"Work ","Work"),ROW($Z$1:$Z$700),1)))*(MID(" "&SUBSTITUTE(SUBSTITUTE(FORMULATEXT('Work 1'!C11),"$",""),"Work ","Work"),ROW($Z$1:$Z$700),1)<>".")*(1-(CODE(MID(SUBSTITUTE(SUBSTITUTE(FORMULATEXT('Work 1'!C11),"$",""),"Work ","Work"),ROW($Z$1:$Z$700),1)&" ")>47)*(CODE(MID(SUBSTITUTE(SUBSTITUTE(FORMULATEXT('Work 1'!C11),"$",""),"Work ","Work"),ROW($Z$1:$Z$700),1)&" ")<51)*(1-(CODE(MID(SUBSTITUTE(SUBSTITUTE(FORMULATEXT('Work 1'!C11),"$",""),"Work ","Work")&" ",ROW($Z$1:$Z$700)+1,1)&" ")>47)*(CODE(MID(SUBSTITUTE(SUBSTITUTE(FORMULATEXT('Work 1'!C11),"$",""),"Work ","Work")&" ",ROW($Z$1:$Z$700)+1,1)&" ")<58))*(MID(SUBSTITUTE(SUBSTITUTE(FORMULATEXT('Work 1'!C11),"$",""),"Work ","Work")&" ",ROW($Z$1:$Z$700)+1,1)<>"."))*(1-(MID(SUBSTITUTE(SUBSTITUTE(FORMULATEXT('Work 1'!C11),"$",""),"Work ","Work"),ROW($Z$1:$Z$700),4)="1000")*(1-(CODE(MID(SUBSTITUTE(SUBSTITUTE(FORMULATEXT('Work 1'!C11),"$",""),"Work ","Work")&" ",ROW($Z$1:$Z$700)+4,1)&" ")>47)*(CODE(MID(SUBSTITUTE(SUBSTITUTE(FORMULATEXT('Work 1'!C11),"$",""),"Work ","Work")&" ",ROW($Z$1:$Z$700)+4,1)&" ")<58))*(MID(SUBSTITUTE(SUBSTITUTE(FORMULATEXT('Work 1'!C11),"$",""),"Work ","Work")&" ",ROW($Z$1:$Z$700)+4,1)<>"."))),0)
A6: 2 | B6: Part A: all 20 items answered. | C6: =IF(COUNTA('Part A'!C5:C24)=20,"OK","CHECK") | G6: Work 1!C12 | H6: =--NOT(ISNA(FORMULATEXT('Work 1'!C12))) | I6: =IFERROR(SUMPRODUCT((CODE(MID(SUBSTITUTE(SUBSTITUTE(FORMULATEXT('Work 1'!C12),"$",""),"Work ","Work"),ROW($Z$1:$Z$700),1)&" ")>47)*(CODE(MID(SUBSTITUTE(SUBSTITUTE(FORMULATEXT('Work 1'!C12),"$",""),"Work ","Work"),ROW($Z$1:$Z$700),1)&" ")<58)*(1-(CODE(MID(" "&SUBSTITUTE(SUBSTITUTE(FORMULATEXT('Work 1'!C12),"$",""),"Work ","Work"),ROW($Z$1:$Z$700),1)&" ")>47)*(CODE(MID(" "&SUBSTITUTE(SUBSTITUTE(FORMULATEXT('Work 1'!C12),"$",""),"Work ","Work"),ROW($Z$1:$Z$700),1)&" ")<58))*EXACT(UPPER(MID(" "&SUBSTITUTE(SUBSTITUTE(FORMULATEXT('Work 1'!C12),"$",""),"Work ","Work"),ROW($Z$1:$Z$700),1)),LOWER(MID(" "&SUBSTITUTE(SUBSTITUTE(FORMULATEXT('Work 1'!C12),"$",""),"Work ","Work"),ROW($Z$1:$Z$700),1)))*(MID(" "&SUBSTITUTE(SUBSTITUTE(FORMULATEXT('Work 1'!C12),"$",""),"Work ","Work"),ROW($Z$1:$Z$700),1)<>".")*(1-(CODE(MID(SUBSTITUTE(SUBSTITUTE(FORMULATEXT('Work 1'!C12),"$",""),"Work ","Work"),ROW($Z$1:$Z$700),1)&" ")>47)*(CODE(MID(SUBSTITUTE(SUBSTITUTE(FORMULATEXT('Work 1'!C12),"$",""),"Work ","Work"),ROW($Z$1:$Z$700),1)&" ")<51)*(1-(CODE(MID(SUBSTITUTE(SUBSTITUTE(FORMULATEXT('Work 1'!C12),"$",""),"Work ","Work")&" ",ROW($Z$1:$Z$700)+1,1)&" ")>47)*(CODE(MID(SUBSTITUTE(SUBSTITUTE(FORMULATEXT('Work 1'!C12),"$",""),"Work ","Work")&" ",ROW($Z$1:$Z$700)+1,1)&" ")<58))*(MID(SUBSTITUTE(SUBSTITUTE(FORMULATEXT('Work 1'!C12),"$",""),"Work ","Work")&" ",ROW($Z$1:$Z$700)+1,1)<>"."))*(1-(MID(SUBSTITUTE(SUBSTITUTE(FORMULATEXT('Work 1'!C12),"$",""),"Work ","Work"),ROW($Z$1:$Z$700),4)="1000")*(1-(CODE(MID(SUBSTITUTE(SUBSTITUTE(FORMULATEXT('Work 1'!C12),"$",""),"Work ","Work")&" ",ROW($Z$1:$Z$700)+4,1)&" ")>47)*(CODE(MID(SUBSTITUTE(SUBSTITUTE(FORMULATEXT('Work 1'!C12),"$",""),"Work ","Work")&" ",ROW($Z$1:$Z$700)+4,1)&" ")<58))*(MID(SUBSTITUTE(SUBSTITUTE(FORMULATEXT('Work 1'!C12),"$",""),"Work ","Work")&" ",ROW($Z$1:$Z$700)+4,1)<>"."))),0)
